[                                 ]   0% de440s.bsp[#################################] 100% de440s.bsp
Traceback (most recent call last):
  File "/home/aweshwep/astrology.jowibtechnologies.com/app/routes/kundali.py", line 161, in api_kundli
    lagna_b64 = generate_kundli_image_jpg(charts["lagna_chart"], chart_type="lagna")
  File "/home/aweshwep/astrology.jowibtechnologies.com/app/utils/kundalichart.py", line 29, in generate_kundli_image_jpg
    img = Image.open(template_path).convert("RGB")
  File "/home/aweshwep/virtualenv/astrology.jowibtechnologies.com/3.10/lib64/python3.10/site-packages/PIL/Image.py", line 3513, in open
    fp = builtins.open(filename, "rb")
FileNotFoundError: [Errno 2] No such file or directory: 'app/static/kundali_north.jpg'
Received JSON payload: {'name': 'Admin', 'gender': 'Female', 'dob': '2002-03-06', 'tob': '19:05', 'place': 'Nadaun', 'user_id': '1'}
Traceback (most recent call last):
  File "/home/aweshwep/astrology.jowibtechnologies.com/app/routes/kundali.py", line 161, in api_kundli
    lagna_b64 = generate_kundli_image_jpg(charts["lagna_chart"], chart_type="lagna")
  File "/home/aweshwep/astrology.jowibtechnologies.com/app/utils/kundalichart.py", line 29, in generate_kundli_image_jpg
    img = Image.open(template_path).convert("RGB")
  File "/home/aweshwep/virtualenv/astrology.jowibtechnologies.com/3.10/lib64/python3.10/site-packages/PIL/Image.py", line 3513, in open
    fp = builtins.open(filename, "rb")
FileNotFoundError: [Errno 2] No such file or directory: 'app/static/kundali_north.jpg'
Traceback (most recent call last):
  File "/home/aweshwep/astrology.jowibtechnologies.com/app/routes/kundali.py", line 161, in api_kundli
    lagna_b64 = generate_kundli_image_jpg(charts["lagna_chart"], chart_type="lagna")
  File "/home/aweshwep/astrology.jowibtechnologies.com/app/utils/kundalichart.py", line 29, in generate_kundli_image_jpg
    img = Image.open(template_path).convert("RGB")
  File "/home/aweshwep/virtualenv/astrology.jowibtechnologies.com/3.10/lib64/python3.10/site-packages/PIL/Image.py", line 3513, in open
    fp = builtins.open(filename, "rb")
FileNotFoundError: [Errno 2] No such file or directory: 'app/static/kundali_north.jpg'
Received JSON payload: {'name': 'Admin', 'gender': 'Female', 'dob': '2002-03-06', 'tob': '19:05', 'place': 'Nadaun', 'user_id': '1'}
Received JSON payload: {'name': 'Admin', 'gender': 'Female', 'dob': '2002-03-06', 'tob': '19:05', 'place': 'Nadaun', 'user_id': '1'}
Received JSON payload: {'name': 'Admin', 'gender': 'Female', 'dob': '2002-03-06', 'tob': '19:05', 'place': 'Nadaun', 'user_id': '1'}
{'nakshatra': 'Purva Ashadha', 'pada': 4, 'personality': 'Spiritual and generous.', 'strengths': ['Charity', 'Philosophy'], 'weaknesses': ['Naivety'], 'career': ['Priest', 'Guru'], 'emotional_traits': 'emotionally intense but caring', 'ideal_partner': 'an adventurous and independent soul', 'keywords': ['invincibility', 'ambition', 'expansion']}
Received JSON payload: {'name': 'Admin', 'gender': 'Female', 'dob': '2002-03-06', 'tob': '19:05', 'place': 'Nadaun', 'user_id': '1'}
Received JSON payload: {'name': 'Admin', 'gender': 'Female', 'dob': '2002-03-06', 'tob': '19:05', 'place': 'Nadaun', 'user_id': '1'}
Received JSON payload: {'name': 'Admin', 'gender': 'Female', 'dob': '2002-03-06', 'tob': '19:05', 'place': 'Nadaun', 'user_id': '1'}
Traceback (most recent call last):
  File "/home/aweshwep/astrology.jowibtechnologies.com/passenger_wsgi.py", line 8, in <module>
    wsgi = imp.load_source('wsgi', 'run.py')
  File "/opt/alt/python310/lib64/python3.10/imp.py", line 172, in load_source
    module = _load(spec)
  File "<frozen importlib._bootstrap>", line 719, in _load
  File "<frozen importlib._bootstrap>", line 688, in _load_unlocked
  File "<frozen importlib._bootstrap_external>", line 883, in exec_module
  File "<frozen importlib._bootstrap>", line 241, in _call_with_frames_removed
  File "run.py", line 1, in <module>
    from app import create_app
  File "/home/aweshwep/astrology.jowibtechnologies.com/app/__init__.py", line 15, in <module>
    app.config['JSON_AS_ASCII'] = False
NameError: name 'app' is not defined
Traceback (most recent call last):
  File "/home/aweshwep/astrology.jowibtechnologies.com/passenger_wsgi.py", line 8, in <module>
    wsgi = imp.load_source('wsgi', 'run.py')
  File "/opt/alt/python310/lib64/python3.10/imp.py", line 172, in load_source
    module = _load(spec)
  File "<frozen importlib._bootstrap>", line 719, in _load
  File "<frozen importlib._bootstrap>", line 688, in _load_unlocked
  File "<frozen importlib._bootstrap_external>", line 883, in exec_module
  File "<frozen importlib._bootstrap>", line 241, in _call_with_frames_removed
  File "run.py", line 1, in <module>
    from app import create_app
  File "/home/aweshwep/astrology.jowibtechnologies.com/app/__init__.py", line 15, in <module>
    app.config['JSON_AS_ASCII'] = False
NameError: name 'app' is not defined
Traceback (most recent call last):
  File "/home/aweshwep/astrology.jowibtechnologies.com/passenger_wsgi.py", line 8, in <module>
    wsgi = imp.load_source('wsgi', 'run.py')
  File "/opt/alt/python310/lib64/python3.10/imp.py", line 172, in load_source
    module = _load(spec)
  File "<frozen importlib._bootstrap>", line 719, in _load
  File "<frozen importlib._bootstrap>", line 688, in _load_unlocked
  File "<frozen importlib._bootstrap_external>", line 883, in exec_module
  File "<frozen importlib._bootstrap>", line 241, in _call_with_frames_removed
  File "run.py", line 1, in <module>
    from app import create_app
  File "/home/aweshwep/astrology.jowibtechnologies.com/app/__init__.py", line 15, in <module>
    app.config['JSON_AS_ASCII'] = False
NameError: name 'app' is not defined
Traceback (most recent call last):
  File "/home/aweshwep/astrology.jowibtechnologies.com/passenger_wsgi.py", line 8, in <module>
    wsgi = imp.load_source('wsgi', 'run.py')
  File "/opt/alt/python310/lib64/python3.10/imp.py", line 172, in load_source
    module = _load(spec)
  File "<frozen importlib._bootstrap>", line 719, in _load
  File "<frozen importlib._bootstrap>", line 688, in _load_unlocked
  File "<frozen importlib._bootstrap_external>", line 883, in exec_module
  File "<frozen importlib._bootstrap>", line 241, in _call_with_frames_removed
  File "run.py", line 1, in <module>
    from app import create_app
  File "/home/aweshwep/astrology.jowibtechnologies.com/app/__init__.py", line 15, in <module>
    app.config['JSON_AS_ASCII'] = False
NameError: name 'app' is not defined
Traceback (most recent call last):
  File "/home/aweshwep/astrology.jowibtechnologies.com/passenger_wsgi.py", line 8, in <module>
    wsgi = imp.load_source('wsgi', 'run.py')
  File "/opt/alt/python310/lib64/python3.10/imp.py", line 172, in load_source
    module = _load(spec)
  File "<frozen importlib._bootstrap>", line 719, in _load
  File "<frozen importlib._bootstrap>", line 688, in _load_unlocked
  File "<frozen importlib._bootstrap_external>", line 883, in exec_module
  File "<frozen importlib._bootstrap>", line 241, in _call_with_frames_removed
  File "run.py", line 1, in <module>
    from app import create_app
  File "/home/aweshwep/astrology.jowibtechnologies.com/app/__init__.py", line 15, in <module>
    app.config['JSON_AS_ASCII'] = False
NameError: name 'app' is not defined
Traceback (most recent call last):
  File "/home/aweshwep/astrology.jowibtechnologies.com/passenger_wsgi.py", line 8, in <module>
    wsgi = imp.load_source('wsgi', 'run.py')
  File "/opt/alt/python310/lib64/python3.10/imp.py", line 172, in load_source
    module = _load(spec)
  File "<frozen importlib._bootstrap>", line 719, in _load
  File "<frozen importlib._bootstrap>", line 688, in _load_unlocked
  File "<frozen importlib._bootstrap_external>", line 883, in exec_module
  File "<frozen importlib._bootstrap>", line 241, in _call_with_frames_removed
  File "run.py", line 1, in <module>
    from app import create_app
  File "/home/aweshwep/astrology.jowibtechnologies.com/app/__init__.py", line 15, in <module>
    app.config['JSON_AS_ASCII'] = False
NameError: name 'app' is not defined
Traceback (most recent call last):
  File "/home/aweshwep/astrology.jowibtechnologies.com/passenger_wsgi.py", line 8, in <module>
    wsgi = imp.load_source('wsgi', 'run.py')
  File "/opt/alt/python310/lib64/python3.10/imp.py", line 172, in load_source
    module = _load(spec)
  File "<frozen importlib._bootstrap>", line 719, in _load
  File "<frozen importlib._bootstrap>", line 688, in _load_unlocked
  File "<frozen importlib._bootstrap_external>", line 883, in exec_module
  File "<frozen importlib._bootstrap>", line 241, in _call_with_frames_removed
  File "run.py", line 1, in <module>
    from app import create_app
  File "/home/aweshwep/astrology.jowibtechnologies.com/app/__init__.py", line 15, in <module>
    app.config['JSON_AS_ASCII'] = False
NameError: name 'app' is not defined
Traceback (most recent call last):
  File "/home/aweshwep/astrology.jowibtechnologies.com/passenger_wsgi.py", line 8, in <module>
    wsgi = imp.load_source('wsgi', 'run.py')
  File "/opt/alt/python310/lib64/python3.10/imp.py", line 172, in load_source
    module = _load(spec)
  File "<frozen importlib._bootstrap>", line 719, in _load
  File "<frozen importlib._bootstrap>", line 688, in _load_unlocked
  File "<frozen importlib._bootstrap_external>", line 883, in exec_module
  File "<frozen importlib._bootstrap>", line 241, in _call_with_frames_removed
  File "run.py", line 1, in <module>
    from app import create_app
  File "/home/aweshwep/astrology.jowibtechnologies.com/app/__init__.py", line 15, in <module>
    app.config['JSON_AS_ASCII'] = False
NameError: name 'app' is not defined
Traceback (most recent call last):
  File "/home/aweshwep/astrology.jowibtechnologies.com/passenger_wsgi.py", line 8, in <module>
    wsgi = imp.load_source('wsgi', 'run.py')
  File "/opt/alt/python310/lib64/python3.10/imp.py", line 172, in load_source
    module = _load(spec)
  File "<frozen importlib._bootstrap>", line 719, in _load
  File "<frozen importlib._bootstrap>", line 688, in _load_unlocked
  File "<frozen importlib._bootstrap_external>", line 883, in exec_module
  File "<frozen importlib._bootstrap>", line 241, in _call_with_frames_removed
  File "run.py", line 9, in <module>
    app.config['JSON_AS_ASCII'] = False
NameError: name 'app' is not defined
Traceback (most recent call last):
  File "/home/aweshwep/astrology.jowibtechnologies.com/passenger_wsgi.py", line 8, in <module>
    wsgi = imp.load_source('wsgi', 'run.py')
  File "/opt/alt/python310/lib64/python3.10/imp.py", line 172, in load_source
    module = _load(spec)
  File "<frozen importlib._bootstrap>", line 719, in _load
  File "<frozen importlib._bootstrap>", line 688, in _load_unlocked
  File "<frozen importlib._bootstrap_external>", line 883, in exec_module
  File "<frozen importlib._bootstrap>", line 241, in _call_with_frames_removed
  File "run.py", line 9, in <module>
    app.config['JSON_AS_ASCII'] = False
NameError: name 'app' is not defined
{'name': 'Admin', 'dob': '2002-03-06', 'radical_number': 6, 'radical_data': {'favourable_sign': 'Taurus, Libra', 'favourable_alphabets': 'U, V, W', 'gemstone': 'Diamond', 'favourable_days': 'Friday, Tuesday', 'favourable_number': '6, 15, 24', 'direction': 'South-East', 'auspicious_color': 'Pink, White', 'ruling_planet': 'Venus', 'god_goddess': 'Lakshmi, Shukracharya', 'fast': 'Friday', 'favourable_dates': '6th, 15th, 24th', 'mantra': 'ॐ शुं शुक्राय नमः', 'personality': 'Responsible, nurturing, harmonious.', 'career': 'Education, beauty, healthcare, art.', 'dos': ['Care for others', 'Stay balanced'], 'donts': ['Avoid being too controlling', 'Don’t ignore self-care'], 'compatibles': [3, 6, 9]}, 'destiny_number': 4, 'destiny_data': {'favourable_sign': 'Aquarius', 'favourable_alphabets': 'D, M, T', 'gemstone': 'Hessonite (Gomed)', 'favourable_days': 'Saturday, Sunday', 'favourable_number': '4, 13, 22, 31', 'direction': 'South-West', 'auspicious_color': 'Electric Blue, Grey', 'ruling_planet': 'Rahu', 'god_goddess': 'Durga, Lord Ganesha', 'fast': 'Saturday', 'favourable_dates': '4th, 13th, 22nd, 31st', 'mantra': 'ॐ रां राहवे नमः', 'personality': 'Practical, disciplined, loyal.', 'career': 'Engineering, construction, security.', 'dos': ['Stick to routine', 'Be consistent'], 'donts': ['Avoid stubbornness', 'Don’t resist change'], 'compatibles': [1, 5, 7]}, 'name_number': 5, 'name_data': {'favourable_sign': 'Gemini, Virgo', 'favourable_alphabets': 'E, H, N, X', 'gemstone': 'Emerald', 'favourable_days': 'Wednesday, Friday', 'favourable_number': '5, 14, 23', 'direction': 'North', 'auspicious_color': 'Green, Light Blue', 'ruling_planet': 'Mercury', 'god_goddess': 'Narayan, Vishnu', 'fast': 'Wednesday', 'favourable_dates': '5th, 14th, 23rd', 'mantra': 'ॐ बुं बुधाय नमः', 'personality': 'Adventurous, dynamic, persuasive.', 'career': 'Sales, marketing, travel, media.', 'dos': ['Take smart risks', 'Stay adaptable'], 'donts': ['Avoid impulsive decisions', 'Don’t overindulge'], 'compatibles': [1, 3, 5]}, 'radical_meaning': 'Responsible, nurturing, family-oriented, artistic.', 'destiny_meaning': 'Practical, hardworking, disciplined, stable.', 'name_meaning': 'Adventurous, versatile, energetic, freedom-loving.', 'numerology_attributes': {'favourable_sign': 'Taurus, Libra', 'favourable_alphabets': 'U, V, W', 'gemstone': 'Diamond', 'favourable_days': 'Friday, Tuesday', 'favourable_number': '6, 15, 24', 'direction': 'South-East', 'auspicious_color': 'Pink, White', 'ruling_planet': 'Venus', 'god_goddess': 'Lakshmi, Shukracharya', 'fast': 'Friday', 'favourable_dates': '6th, 15th, 24th', 'mantra': 'ॐ शुं शुक्राय नमः', 'personality': 'Responsible, nurturing, harmonious.', 'career': 'Education, beauty, healthcare, art.', 'dos': ['Care for others', 'Stay balanced'], 'donts': ['Avoid being too controlling', 'Don’t ignore self-care'], 'compatibles': [3, 6, 9]}}
[                                 ]   0% de421.bsp[#################################] 100% de421.bsp
{'nakshatra': 'Purva Ashadha', 'pada': 4, 'personality': 'Spiritual and generous.', 'strengths': ['Charity', 'Philosophy'], 'weaknesses': ['Naivety'], 'career': ['Priest', 'Guru'], 'emotional_traits': 'emotionally intense but caring', 'ideal_partner': 'an adventurous and independent soul', 'keywords': ['invincibility', 'ambition', 'expansion']}
{'nakshatra': 'Purva Ashadha', 'pada': 4, 'personality': 'Spiritual and generous.', 'strengths': ['Charity', 'Philosophy'], 'weaknesses': ['Naivety'], 'career': ['Priest', 'Guru'], 'emotional_traits': 'emotionally intense but caring', 'ideal_partner': 'an adventurous and independent soul', 'keywords': ['invincibility', 'ambition', 'expansion']}
Received JSON payload: {'name': 'Admin', 'gender': 'Female', 'dob': '2002-03-06', 'tob': '19:05', 'place': 'Nadaun', 'user_id': '1'}
Received JSON payload: {'name': 'Admin', 'gender': 'Female', 'dob': '2002-03-06', 'tob': '19:05', 'place': 'Nadaun', 'user_id': '1'}
Received JSON payload: {'name': 'Shivangi', 'gender': 'Female', 'dob': '2002-03-06', 'tob': '19:05', 'place': 'Nadaun', 'user_id': '1'}
Received JSON payload: {'name': 'Admin', 'gender': 'Female', 'dob': '2002-03-06', 'tob': '19:05', 'place': 'Nadaun', 'user_id': '1'}
[ERROR] [UID:601][2939799] wsgiAppHandler pApp->start_response() return NULL.
Traceback (most recent call last):
  File "/home/aweshwep/virtualenv/astrology.jowibtechnologies.com/3.10/lib64/python3.10/site-packages/sqlalchemy/engine/base.py", line 1122, in _rollback_impl
    self.engine.dialect.do_rollback(self.connection)
  File "/home/aweshwep/virtualenv/astrology.jowibtechnologies.com/3.10/lib64/python3.10/site-packages/sqlalchemy/engine/default.py", line 704, in do_rollback
    dbapi_connection.rollback()
  File "/home/aweshwep/virtualenv/astrology.jowibtechnologies.com/3.10/lib/python3.10/site-packages/pymysql/connections.py", line 493, in rollback
    self._read_ok_packet()
  File "/home/aweshwep/virtualenv/astrology.jowibtechnologies.com/3.10/lib/python3.10/site-packages/pymysql/connections.py", line 455, in _read_ok_packet
    raise err.OperationalError(
pymysql.err.OperationalError: (2014, 'Command Out of Sync')

The above exception was the direct cause of the following exception:

Traceback (most recent call last):
  File "/home/aweshwep/virtualenv/astrology.jowibtechnologies.com/3.10/lib/python3.10/site-packages/flask/app.py", line 1536, in __call__
    return self.wsgi_app(environ, start_response)
  File "/home/aweshwep/virtualenv/astrology.jowibtechnologies.com/3.10/lib/python3.10/site-packages/flask/app.py", line 1527, in wsgi_app
    ctx.pop(error)
  File "/home/aweshwep/virtualenv/astrology.jowibtechnologies.com/3.10/lib/python3.10/site-packages/flask/ctx.py", line 426, in pop
    app_ctx.pop(exc)
  File "/home/aweshwep/virtualenv/astrology.jowibtechnologies.com/3.10/lib/python3.10/site-packages/flask/ctx.py", line 262, in pop
    self.app.do_teardown_appcontext(exc)
  File "/home/aweshwep/virtualenv/astrology.jowibtechnologies.com/3.10/lib/python3.10/site-packages/flask/app.py", line 1382, in do_teardown_appcontext
    self.ensure_sync(func)(exc)
  File "/home/aweshwep/virtualenv/astrology.jowibtechnologies.com/3.10/lib/python3.10/site-packages/flask_sqlalchemy/extension.py", line 448, in _teardown_session
    self.session.remove()
  File "/home/aweshwep/virtualenv/astrology.jowibtechnologies.com/3.10/lib64/python3.10/site-packages/sqlalchemy/orm/scoping.py", line 261, in remove
    self.registry().close()
  File "/home/aweshwep/virtualenv/astrology.jowibtechnologies.com/3.10/lib64/python3.10/site-packages/sqlalchemy/orm/session.py", line 2521, in close
    self._close_impl(invalidate=False)
  File "/home/aweshwep/virtualenv/astrology.jowibtechnologies.com/3.10/lib64/python3.10/site-packages/sqlalchemy/orm/session.py", line 2590, in _close_impl
    transaction.close(invalidate)
  File "<string>", line 2, in close
  File "/home/aweshwep/virtualenv/astrology.jowibtechnologies.com/3.10/lib64/python3.10/site-packages/sqlalchemy/orm/state_changes.py", line 137, in _go
    ret_value = fn(self, *arg, **kw)
  File "/home/aweshwep/virtualenv/astrology.jowibtechnologies.com/3.10/lib64/python3.10/site-packages/sqlalchemy/orm/session.py", line 1419, in close
    transaction.close()
  File "/home/aweshwep/virtualenv/astrology.jowibtechnologies.com/3.10/lib64/python3.10/site-packages/sqlalchemy/engine/base.py", line 2583, in close
    self._do_close()
  File "/home/aweshwep/virtualenv/astrology.jowibtechnologies.com/3.10/lib64/python3.10/site-packages/sqlalchemy/engine/base.py", line 2721, in _do_close
    self._close_impl()
  File "/home/aweshwep/virtualenv/astrology.jowibtechnologies.com/3.10/lib64/python3.10/site-packages/sqlalchemy/engine/base.py", line 2707, in _close_impl
    self._connection_rollback_impl()
  File "/home/aweshwep/virtualenv/astrology.jowibtechnologies.com/3.10/lib64/python3.10/site-packages/sqlalchemy/engine/base.py", line 2699, in _connection_rollback_impl
    self.connection._rollback_impl()
  File "/home/aweshwep/virtualenv/astrology.jowibtechnologies.com/3.10/lib64/python3.10/site-packages/sqlalchemy/engine/base.py", line 1124, in _rollback_impl
    self._handle_dbapi_exception(e, None, None, None, None)
  File "/home/aweshwep/virtualenv/astrology.jowibtechnologies.com/3.10/lib64/python3.10/site-packages/sqlalchemy/engine/base.py", line 2349, in _handle_dbapi_exception
    raise sqlalchemy_exception.with_traceback(exc_info[2]) from e
  File "/home/aweshwep/virtualenv/astrology.jowibtechnologies.com/3.10/lib64/python3.10/site-packages/sqlalchemy/engine/base.py", line 1122, in _rollback_impl
    self.engine.dialect.do_rollback(self.connection)
  File "/home/aweshwep/virtualenv/astrology.jowibtechnologies.com/3.10/lib64/python3.10/site-packages/sqlalchemy/engine/default.py", line 704, in do_rollback
    dbapi_connection.rollback()
  File "/home/aweshwep/virtualenv/astrology.jowibtechnologies.com/3.10/lib/python3.10/site-packages/pymysql/connections.py", line 493, in rollback
    self._read_ok_packet()
  File "/home/aweshwep/virtualenv/astrology.jowibtechnologies.com/3.10/lib/python3.10/site-packages/pymysql/connections.py", line 455, in _read_ok_packet
    raise err.OperationalError(
sqlalchemy.exc.OperationalError: (pymysql.err.OperationalError) (2014, 'Command Out of Sync')
(Background on this error at: https://sqlalche.me/e/20/e3q8)
[2025-08-14 00:57:06,651] ERROR in app: Exception on /api/services [GET]
Traceback (most recent call last):
  File "/home/aweshwep/virtualenv/astrology.jowibtechnologies.com/3.10/lib/python3.10/site-packages/flask/app.py", line 1511, in wsgi_app
    response = self.full_dispatch_request()
  File "/home/aweshwep/virtualenv/astrology.jowibtechnologies.com/3.10/lib/python3.10/site-packages/flask/app.py", line 919, in full_dispatch_request
    rv = self.handle_user_exception(e)
  File "/home/aweshwep/virtualenv/astrology.jowibtechnologies.com/3.10/lib/python3.10/site-packages/flask_cors/extension.py", line 176, in wrapped_function
    return cors_after_request(app.make_response(f(*args, **kwargs)))
  File "/home/aweshwep/virtualenv/astrology.jowibtechnologies.com/3.10/lib/python3.10/site-packages/flask/app.py", line 917, in full_dispatch_request
    rv = self.dispatch_request()
  File "/home/aweshwep/virtualenv/astrology.jowibtechnologies.com/3.10/lib/python3.10/site-packages/flask/app.py", line 902, in dispatch_request
    return self.ensure_sync(self.view_functions[rule.endpoint])(**view_args)  # type: ignore[no-any-return]
  File "/home/aweshwep/astrology.jowibtechnologies.com/app/routes/services.py", line 8, in get_services
    services = Service.query.all()
  File "/home/aweshwep/virtualenv/astrology.jowibtechnologies.com/3.10/lib64/python3.10/site-packages/sqlalchemy/orm/query.py", line 2704, in all
    return self._iter().all()  # type: ignore
  File "/home/aweshwep/virtualenv/astrology.jowibtechnologies.com/3.10/lib64/python3.10/site-packages/sqlalchemy/orm/query.py", line 2857, in _iter
    result: Union[ScalarResult[_T], Result[_T]] = self.session.execute(
  File "/home/aweshwep/virtualenv/astrology.jowibtechnologies.com/3.10/lib64/python3.10/site-packages/sqlalchemy/orm/session.py", line 2365, in execute
    return self._execute_internal(
  File "/home/aweshwep/virtualenv/astrology.jowibtechnologies.com/3.10/lib64/python3.10/site-packages/sqlalchemy/orm/session.py", line 2251, in _execute_internal
    result: Result[Any] = compile_state_cls.orm_execute_statement(
  File "/home/aweshwep/virtualenv/astrology.jowibtechnologies.com/3.10/lib64/python3.10/site-packages/sqlalchemy/orm/context.py", line 309, in orm_execute_statement
    return cls.orm_setup_cursor_result(
  File "/home/aweshwep/virtualenv/astrology.jowibtechnologies.com/3.10/lib64/python3.10/site-packages/sqlalchemy/orm/context.py", line 616, in orm_setup_cursor_result
    return loading.instances(result, querycontext)
  File "/home/aweshwep/virtualenv/astrology.jowibtechnologies.com/3.10/lib64/python3.10/site-packages/sqlalchemy/orm/loading.py", line 132, in instances
    with util.safe_reraise():
  File "/home/aweshwep/virtualenv/astrology.jowibtechnologies.com/3.10/lib64/python3.10/site-packages/sqlalchemy/util/langhelpers.py", line 224, in __exit__
    raise exc_value.with_traceback(exc_tb)
  File "/home/aweshwep/virtualenv/astrology.jowibtechnologies.com/3.10/lib64/python3.10/site-packages/sqlalchemy/orm/loading.py", line 113, in instances
    *[
  File "/home/aweshwep/virtualenv/astrology.jowibtechnologies.com/3.10/lib64/python3.10/site-packages/sqlalchemy/orm/loading.py", line 114, in <listcomp>
    query_entity.row_processor(context, cursor)
  File "/home/aweshwep/virtualenv/astrology.jowibtechnologies.com/3.10/lib64/python3.10/site-packages/sqlalchemy/orm/context.py", line 2786, in row_processor
    _instance = loading._instance_processor(
  File "/home/aweshwep/virtualenv/astrology.jowibtechnologies.com/3.10/lib64/python3.10/site-packages/sqlalchemy/orm/loading.py", line 877, in _instance_processor
    primary_key_getter = result._tuple_getter(pk_cols)
  File "/home/aweshwep/virtualenv/astrology.jowibtechnologies.com/3.10/lib64/python3.10/site-packages/sqlalchemy/engine/result.py", line 1189, in _tuple_getter
    return self._metadata._row_as_tuple_getter(keys)
  File "/home/aweshwep/virtualenv/astrology.jowibtechnologies.com/3.10/lib64/python3.10/site-packages/sqlalchemy/engine/result.py", line 179, in _row_as_tuple_getter
    indexes = self._indexes_for_keys(keys)
  File "/home/aweshwep/virtualenv/astrology.jowibtechnologies.com/3.10/lib64/python3.10/site-packages/sqlalchemy/engine/result.py", line 156, in _indexes_for_keys
    raise NotImplementedError()
NotImplementedError
[ERROR] [UID:601][2939798] wsgiAppHandler pApp->start_response() return NULL.
Traceback (most recent call last):
  File "/home/aweshwep/virtualenv/astrology.jowibtechnologies.com/3.10/lib64/python3.10/site-packages/sqlalchemy/engine/base.py", line 1122, in _rollback_impl
    self.engine.dialect.do_rollback(self.connection)
  File "/home/aweshwep/virtualenv/astrology.jowibtechnologies.com/3.10/lib64/python3.10/site-packages/sqlalchemy/engine/default.py", line 704, in do_rollback
    dbapi_connection.rollback()
  File "/home/aweshwep/virtualenv/astrology.jowibtechnologies.com/3.10/lib/python3.10/site-packages/pymysql/connections.py", line 493, in rollback
    self._read_ok_packet()
  File "/home/aweshwep/virtualenv/astrology.jowibtechnologies.com/3.10/lib/python3.10/site-packages/pymysql/connections.py", line 453, in _read_ok_packet
    pkt = self._read_packet()
  File "/home/aweshwep/virtualenv/astrology.jowibtechnologies.com/3.10/lib/python3.10/site-packages/pymysql/connections.py", line 744, in _read_packet
    packet_header = self._read_bytes(4)
  File "/home/aweshwep/virtualenv/astrology.jowibtechnologies.com/3.10/lib/python3.10/site-packages/pymysql/connections.py", line 798, in _read_bytes
    raise err.OperationalError(
pymysql.err.OperationalError: (2013, 'Lost connection to MySQL server during query')

The above exception was the direct cause of the following exception:

Traceback (most recent call last):
  File "/home/aweshwep/virtualenv/astrology.jowibtechnologies.com/3.10/lib/python3.10/site-packages/flask/app.py", line 1536, in __call__
    return self.wsgi_app(environ, start_response)
  File "/home/aweshwep/virtualenv/astrology.jowibtechnologies.com/3.10/lib/python3.10/site-packages/flask/app.py", line 1527, in wsgi_app
    ctx.pop(error)
  File "/home/aweshwep/virtualenv/astrology.jowibtechnologies.com/3.10/lib/python3.10/site-packages/flask/ctx.py", line 426, in pop
    app_ctx.pop(exc)
  File "/home/aweshwep/virtualenv/astrology.jowibtechnologies.com/3.10/lib/python3.10/site-packages/flask/ctx.py", line 262, in pop
    self.app.do_teardown_appcontext(exc)
  File "/home/aweshwep/virtualenv/astrology.jowibtechnologies.com/3.10/lib/python3.10/site-packages/flask/app.py", line 1382, in do_teardown_appcontext
    self.ensure_sync(func)(exc)
  File "/home/aweshwep/virtualenv/astrology.jowibtechnologies.com/3.10/lib/python3.10/site-packages/flask_sqlalchemy/extension.py", line 448, in _teardown_session
    self.session.remove()
  File "/home/aweshwep/virtualenv/astrology.jowibtechnologies.com/3.10/lib64/python3.10/site-packages/sqlalchemy/orm/scoping.py", line 261, in remove
    self.registry().close()
  File "/home/aweshwep/virtualenv/astrology.jowibtechnologies.com/3.10/lib64/python3.10/site-packages/sqlalchemy/orm/session.py", line 2521, in close
    self._close_impl(invalidate=False)
  File "/home/aweshwep/virtualenv/astrology.jowibtechnologies.com/3.10/lib64/python3.10/site-packages/sqlalchemy/orm/session.py", line 2590, in _close_impl
    transaction.close(invalidate)
  File "<string>", line 2, in close
  File "/home/aweshwep/virtualenv/astrology.jowibtechnologies.com/3.10/lib64/python3.10/site-packages/sqlalchemy/orm/state_changes.py", line 137, in _go
    ret_value = fn(self, *arg, **kw)
  File "/home/aweshwep/virtualenv/astrology.jowibtechnologies.com/3.10/lib64/python3.10/site-packages/sqlalchemy/orm/session.py", line 1419, in close
    transaction.close()
  File "/home/aweshwep/virtualenv/astrology.jowibtechnologies.com/3.10/lib64/python3.10/site-packages/sqlalchemy/engine/base.py", line 2583, in close
    self._do_close()
  File "/home/aweshwep/virtualenv/astrology.jowibtechnologies.com/3.10/lib64/python3.10/site-packages/sqlalchemy/engine/base.py", line 2721, in _do_close
    self._close_impl()
  File "/home/aweshwep/virtualenv/astrology.jowibtechnologies.com/3.10/lib64/python3.10/site-packages/sqlalchemy/engine/base.py", line 2707, in _close_impl
    self._connection_rollback_impl()
  File "/home/aweshwep/virtualenv/astrology.jowibtechnologies.com/3.10/lib64/python3.10/site-packages/sqlalchemy/engine/base.py", line 2699, in _connection_rollback_impl
    self.connection._rollback_impl()
  File "/home/aweshwep/virtualenv/astrology.jowibtechnologies.com/3.10/lib64/python3.10/site-packages/sqlalchemy/engine/base.py", line 1124, in _rollback_impl
    self._handle_dbapi_exception(e, None, None, None, None)
  File "/home/aweshwep/virtualenv/astrology.jowibtechnologies.com/3.10/lib64/python3.10/site-packages/sqlalchemy/engine/base.py", line 2349, in _handle_dbapi_exception
    raise sqlalchemy_exception.with_traceback(exc_info[2]) from e
  File "/home/aweshwep/virtualenv/astrology.jowibtechnologies.com/3.10/lib64/python3.10/site-packages/sqlalchemy/engine/base.py", line 1122, in _rollback_impl
    self.engine.dialect.do_rollback(self.connection)
  File "/home/aweshwep/virtualenv/astrology.jowibtechnologies.com/3.10/lib64/python3.10/site-packages/sqlalchemy/engine/default.py", line 704, in do_rollback
    dbapi_connection.rollback()
  File "/home/aweshwep/virtualenv/astrology.jowibtechnologies.com/3.10/lib/python3.10/site-packages/pymysql/connections.py", line 493, in rollback
    self._read_ok_packet()
  File "/home/aweshwep/virtualenv/astrology.jowibtechnologies.com/3.10/lib/python3.10/site-packages/pymysql/connections.py", line 453, in _read_ok_packet
    pkt = self._read_packet()
  File "/home/aweshwep/virtualenv/astrology.jowibtechnologies.com/3.10/lib/python3.10/site-packages/pymysql/connections.py", line 744, in _read_packet
    packet_header = self._read_bytes(4)
  File "/home/aweshwep/virtualenv/astrology.jowibtechnologies.com/3.10/lib/python3.10/site-packages/pymysql/connections.py", line 798, in _read_bytes
    raise err.OperationalError(
sqlalchemy.exc.OperationalError: (pymysql.err.OperationalError) (2013, 'Lost connection to MySQL server during query')
(Background on this error at: https://sqlalche.me/e/20/e3q8)
[2025-08-14 00:57:17,860] ERROR in app: Exception on /api/services [GET]
Traceback (most recent call last):
  File "/home/aweshwep/virtualenv/astrology.jowibtechnologies.com/3.10/lib/python3.10/site-packages/pymysql/connections.py", line 806, in _write_bytes
    self._sock.sendall(data)
BrokenPipeError: [Errno 32] Broken pipe

During handling of the above exception, another exception occurred:

Traceback (most recent call last):
  File "/home/aweshwep/virtualenv/astrology.jowibtechnologies.com/3.10/lib64/python3.10/site-packages/sqlalchemy/engine/base.py", line 1961, in _exec_single_context
    self.dialect.do_execute(
  File "/home/aweshwep/virtualenv/astrology.jowibtechnologies.com/3.10/lib64/python3.10/site-packages/sqlalchemy/engine/default.py", line 944, in do_execute
    cursor.execute(statement, parameters)
  File "/home/aweshwep/virtualenv/astrology.jowibtechnologies.com/3.10/lib/python3.10/site-packages/pymysql/cursors.py", line 153, in execute
    result = self._query(query)
  File "/home/aweshwep/virtualenv/astrology.jowibtechnologies.com/3.10/lib/python3.10/site-packages/pymysql/cursors.py", line 322, in _query
    conn.query(q)
  File "/home/aweshwep/virtualenv/astrology.jowibtechnologies.com/3.10/lib/python3.10/site-packages/pymysql/connections.py", line 562, in query
    self._execute_command(COMMAND.COM_QUERY, sql)
  File "/home/aweshwep/virtualenv/astrology.jowibtechnologies.com/3.10/lib/python3.10/site-packages/pymysql/connections.py", line 864, in _execute_command
    self._write_bytes(packet)
  File "/home/aweshwep/virtualenv/astrology.jowibtechnologies.com/3.10/lib/python3.10/site-packages/pymysql/connections.py", line 809, in _write_bytes
    raise err.OperationalError(
pymysql.err.OperationalError: (2006, "MySQL server has gone away (BrokenPipeError(32, 'Broken pipe'))")

The above exception was the direct cause of the following exception:

Traceback (most recent call last):
  File "/home/aweshwep/virtualenv/astrology.jowibtechnologies.com/3.10/lib/python3.10/site-packages/flask/app.py", line 1511, in wsgi_app
    response = self.full_dispatch_request()
  File "/home/aweshwep/virtualenv/astrology.jowibtechnologies.com/3.10/lib/python3.10/site-packages/flask/app.py", line 919, in full_dispatch_request
    rv = self.handle_user_exception(e)
  File "/home/aweshwep/virtualenv/astrology.jowibtechnologies.com/3.10/lib/python3.10/site-packages/flask_cors/extension.py", line 176, in wrapped_function
    return cors_after_request(app.make_response(f(*args, **kwargs)))
  File "/home/aweshwep/virtualenv/astrology.jowibtechnologies.com/3.10/lib/python3.10/site-packages/flask/app.py", line 917, in full_dispatch_request
    rv = self.dispatch_request()
  File "/home/aweshwep/virtualenv/astrology.jowibtechnologies.com/3.10/lib/python3.10/site-packages/flask/app.py", line 902, in dispatch_request
    return self.ensure_sync(self.view_functions[rule.endpoint])(**view_args)  # type: ignore[no-any-return]
  File "/home/aweshwep/astrology.jowibtechnologies.com/app/routes/services.py", line 8, in get_services
    services = Service.query.all()
  File "/home/aweshwep/virtualenv/astrology.jowibtechnologies.com/3.10/lib64/python3.10/site-packages/sqlalchemy/orm/query.py", line 2704, in all
    return self._iter().all()  # type: ignore
  File "/home/aweshwep/virtualenv/astrology.jowibtechnologies.com/3.10/lib64/python3.10/site-packages/sqlalchemy/orm/query.py", line 2857, in _iter
    result: Union[ScalarResult[_T], Result[_T]] = self.session.execute(
  File "/home/aweshwep/virtualenv/astrology.jowibtechnologies.com/3.10/lib64/python3.10/site-packages/sqlalchemy/orm/session.py", line 2365, in execute
    return self._execute_internal(
  File "/home/aweshwep/virtualenv/astrology.jowibtechnologies.com/3.10/lib64/python3.10/site-packages/sqlalchemy/orm/session.py", line 2251, in _execute_internal
    result: Result[Any] = compile_state_cls.orm_execute_statement(
  File "/home/aweshwep/virtualenv/astrology.jowibtechnologies.com/3.10/lib64/python3.10/site-packages/sqlalchemy/orm/context.py", line 306, in orm_execute_statement
    result = conn.execute(
  File "/home/aweshwep/virtualenv/astrology.jowibtechnologies.com/3.10/lib64/python3.10/site-packages/sqlalchemy/engine/base.py", line 1413, in execute
    return meth(
  File "/home/aweshwep/virtualenv/astrology.jowibtechnologies.com/3.10/lib64/python3.10/site-packages/sqlalchemy/sql/elements.py", line 526, in _execute_on_connection
    return connection._execute_clauseelement(
  File "/home/aweshwep/virtualenv/astrology.jowibtechnologies.com/3.10/lib64/python3.10/site-packages/sqlalchemy/engine/base.py", line 1635, in _execute_clauseelement
    ret = self._execute_context(
  File "/home/aweshwep/virtualenv/astrology.jowibtechnologies.com/3.10/lib64/python3.10/site-packages/sqlalchemy/engine/base.py", line 1840, in _execute_context
    return self._exec_single_context(
  File "/home/aweshwep/virtualenv/astrology.jowibtechnologies.com/3.10/lib64/python3.10/site-packages/sqlalchemy/engine/base.py", line 1980, in _exec_single_context
    self._handle_dbapi_exception(
  File "/home/aweshwep/virtualenv/astrology.jowibtechnologies.com/3.10/lib64/python3.10/site-packages/sqlalchemy/engine/base.py", line 2349, in _handle_dbapi_exception
    raise sqlalchemy_exception.with_traceback(exc_info[2]) from e
  File "/home/aweshwep/virtualenv/astrology.jowibtechnologies.com/3.10/lib64/python3.10/site-packages/sqlalchemy/engine/base.py", line 1961, in _exec_single_context
    self.dialect.do_execute(
  File "/home/aweshwep/virtualenv/astrology.jowibtechnologies.com/3.10/lib64/python3.10/site-packages/sqlalchemy/engine/default.py", line 944, in do_execute
    cursor.execute(statement, parameters)
  File "/home/aweshwep/virtualenv/astrology.jowibtechnologies.com/3.10/lib/python3.10/site-packages/pymysql/cursors.py", line 153, in execute
    result = self._query(query)
  File "/home/aweshwep/virtualenv/astrology.jowibtechnologies.com/3.10/lib/python3.10/site-packages/pymysql/cursors.py", line 322, in _query
    conn.query(q)
  File "/home/aweshwep/virtualenv/astrology.jowibtechnologies.com/3.10/lib/python3.10/site-packages/pymysql/connections.py", line 562, in query
    self._execute_command(COMMAND.COM_QUERY, sql)
  File "/home/aweshwep/virtualenv/astrology.jowibtechnologies.com/3.10/lib/python3.10/site-packages/pymysql/connections.py", line 864, in _execute_command
    self._write_bytes(packet)
  File "/home/aweshwep/virtualenv/astrology.jowibtechnologies.com/3.10/lib/python3.10/site-packages/pymysql/connections.py", line 809, in _write_bytes
    raise err.OperationalError(
sqlalchemy.exc.OperationalError: (pymysql.err.OperationalError) (2006, "MySQL server has gone away (BrokenPipeError(32, 'Broken pipe'))")
[SQL: SELECT services.id AS services_id, services.card_id AS services_card_id, services.title AS services_title, services.img AS services_img, services.description AS services_description, services.route AS services_route, services.link AS services_link, services.fields AS services_fields 
FROM services]
(Background on this error at: https://sqlalche.me/e/20/e3q8)
[2025-08-14 02:17:34,847] ERROR in app: Exception on /api/services [GET]
Traceback (most recent call last):
  File "/home/aweshwep/virtualenv/astrology.jowibtechnologies.com/3.10/lib/python3.10/site-packages/flask/app.py", line 1511, in wsgi_app
    response = self.full_dispatch_request()
  File "/home/aweshwep/virtualenv/astrology.jowibtechnologies.com/3.10/lib/python3.10/site-packages/flask/app.py", line 919, in full_dispatch_request
    rv = self.handle_user_exception(e)
  File "/home/aweshwep/virtualenv/astrology.jowibtechnologies.com/3.10/lib/python3.10/site-packages/flask_cors/extension.py", line 176, in wrapped_function
    return cors_after_request(app.make_response(f(*args, **kwargs)))
  File "/home/aweshwep/virtualenv/astrology.jowibtechnologies.com/3.10/lib/python3.10/site-packages/flask/app.py", line 917, in full_dispatch_request
    rv = self.dispatch_request()
  File "/home/aweshwep/virtualenv/astrology.jowibtechnologies.com/3.10/lib/python3.10/site-packages/flask/app.py", line 902, in dispatch_request
    return self.ensure_sync(self.view_functions[rule.endpoint])(**view_args)  # type: ignore[no-any-return]
  File "/home/aweshwep/astrology.jowibtechnologies.com/app/routes/services.py", line 8, in get_services
    services = Service.query.all()
  File "/home/aweshwep/virtualenv/astrology.jowibtechnologies.com/3.10/lib64/python3.10/site-packages/sqlalchemy/orm/query.py", line 2704, in all
    return self._iter().all()  # type: ignore
  File "/home/aweshwep/virtualenv/astrology.jowibtechnologies.com/3.10/lib64/python3.10/site-packages/sqlalchemy/orm/query.py", line 2857, in _iter
    result: Union[ScalarResult[_T], Result[_T]] = self.session.execute(
  File "/home/aweshwep/virtualenv/astrology.jowibtechnologies.com/3.10/lib64/python3.10/site-packages/sqlalchemy/orm/session.py", line 2365, in execute
    return self._execute_internal(
  File "/home/aweshwep/virtualenv/astrology.jowibtechnologies.com/3.10/lib64/python3.10/site-packages/sqlalchemy/orm/session.py", line 2251, in _execute_internal
    result: Result[Any] = compile_state_cls.orm_execute_statement(
  File "/home/aweshwep/virtualenv/astrology.jowibtechnologies.com/3.10/lib64/python3.10/site-packages/sqlalchemy/orm/context.py", line 309, in orm_execute_statement
    return cls.orm_setup_cursor_result(
  File "/home/aweshwep/virtualenv/astrology.jowibtechnologies.com/3.10/lib64/python3.10/site-packages/sqlalchemy/orm/context.py", line 616, in orm_setup_cursor_result
    return loading.instances(result, querycontext)
  File "/home/aweshwep/virtualenv/astrology.jowibtechnologies.com/3.10/lib64/python3.10/site-packages/sqlalchemy/orm/loading.py", line 132, in instances
    with util.safe_reraise():
  File "/home/aweshwep/virtualenv/astrology.jowibtechnologies.com/3.10/lib64/python3.10/site-packages/sqlalchemy/util/langhelpers.py", line 224, in __exit__
    raise exc_value.with_traceback(exc_tb)
  File "/home/aweshwep/virtualenv/astrology.jowibtechnologies.com/3.10/lib64/python3.10/site-packages/sqlalchemy/orm/loading.py", line 113, in instances
    *[
  File "/home/aweshwep/virtualenv/astrology.jowibtechnologies.com/3.10/lib64/python3.10/site-packages/sqlalchemy/orm/loading.py", line 114, in <listcomp>
    query_entity.row_processor(context, cursor)
  File "/home/aweshwep/virtualenv/astrology.jowibtechnologies.com/3.10/lib64/python3.10/site-packages/sqlalchemy/orm/context.py", line 2786, in row_processor
    _instance = loading._instance_processor(
  File "/home/aweshwep/virtualenv/astrology.jowibtechnologies.com/3.10/lib64/python3.10/site-packages/sqlalchemy/orm/loading.py", line 877, in _instance_processor
    primary_key_getter = result._tuple_getter(pk_cols)
  File "/home/aweshwep/virtualenv/astrology.jowibtechnologies.com/3.10/lib64/python3.10/site-packages/sqlalchemy/engine/result.py", line 1189, in _tuple_getter
    return self._metadata._row_as_tuple_getter(keys)
  File "/home/aweshwep/virtualenv/astrology.jowibtechnologies.com/3.10/lib64/python3.10/site-packages/sqlalchemy/engine/result.py", line 179, in _row_as_tuple_getter
    indexes = self._indexes_for_keys(keys)
  File "/home/aweshwep/virtualenv/astrology.jowibtechnologies.com/3.10/lib64/python3.10/site-packages/sqlalchemy/engine/result.py", line 156, in _indexes_for_keys
    raise NotImplementedError()
NotImplementedError
[ERROR] [UID:601][3745224] wsgiAppHandler pApp->start_response() return NULL.
Traceback (most recent call last):
  File "/home/aweshwep/virtualenv/astrology.jowibtechnologies.com/3.10/lib64/python3.10/site-packages/sqlalchemy/engine/base.py", line 1122, in _rollback_impl
    self.engine.dialect.do_rollback(self.connection)
  File "/home/aweshwep/virtualenv/astrology.jowibtechnologies.com/3.10/lib64/python3.10/site-packages/sqlalchemy/engine/default.py", line 704, in do_rollback
    dbapi_connection.rollback()
  File "/home/aweshwep/virtualenv/astrology.jowibtechnologies.com/3.10/lib/python3.10/site-packages/pymysql/connections.py", line 493, in rollback
    self._read_ok_packet()
  File "/home/aweshwep/virtualenv/astrology.jowibtechnologies.com/3.10/lib/python3.10/site-packages/pymysql/connections.py", line 455, in _read_ok_packet
    raise err.OperationalError(
pymysql.err.OperationalError: (2014, 'Command Out of Sync')

The above exception was the direct cause of the following exception:

Traceback (most recent call last):
  File "/home/aweshwep/virtualenv/astrology.jowibtechnologies.com/3.10/lib/python3.10/site-packages/flask/app.py", line 1536, in __call__
    return self.wsgi_app(environ, start_response)
  File "/home/aweshwep/virtualenv/astrology.jowibtechnologies.com/3.10/lib/python3.10/site-packages/flask/app.py", line 1527, in wsgi_app
    ctx.pop(error)
  File "/home/aweshwep/virtualenv/astrology.jowibtechnologies.com/3.10/lib/python3.10/site-packages/flask/ctx.py", line 426, in pop
    app_ctx.pop(exc)
  File "/home/aweshwep/virtualenv/astrology.jowibtechnologies.com/3.10/lib/python3.10/site-packages/flask/ctx.py", line 262, in pop
    self.app.do_teardown_appcontext(exc)
  File "/home/aweshwep/virtualenv/astrology.jowibtechnologies.com/3.10/lib/python3.10/site-packages/flask/app.py", line 1382, in do_teardown_appcontext
    self.ensure_sync(func)(exc)
  File "/home/aweshwep/virtualenv/astrology.jowibtechnologies.com/3.10/lib/python3.10/site-packages/flask_sqlalchemy/extension.py", line 448, in _teardown_session
    self.session.remove()
  File "/home/aweshwep/virtualenv/astrology.jowibtechnologies.com/3.10/lib64/python3.10/site-packages/sqlalchemy/orm/scoping.py", line 261, in remove
    self.registry().close()
  File "/home/aweshwep/virtualenv/astrology.jowibtechnologies.com/3.10/lib64/python3.10/site-packages/sqlalchemy/orm/session.py", line 2521, in close
    self._close_impl(invalidate=False)
  File "/home/aweshwep/virtualenv/astrology.jowibtechnologies.com/3.10/lib64/python3.10/site-packages/sqlalchemy/orm/session.py", line 2590, in _close_impl
    transaction.close(invalidate)
  File "<string>", line 2, in close
  File "/home/aweshwep/virtualenv/astrology.jowibtechnologies.com/3.10/lib64/python3.10/site-packages/sqlalchemy/orm/state_changes.py", line 137, in _go
    ret_value = fn(self, *arg, **kw)
  File "/home/aweshwep/virtualenv/astrology.jowibtechnologies.com/3.10/lib64/python3.10/site-packages/sqlalchemy/orm/session.py", line 1419, in close
    transaction.close()
  File "/home/aweshwep/virtualenv/astrology.jowibtechnologies.com/3.10/lib64/python3.10/site-packages/sqlalchemy/engine/base.py", line 2583, in close
    self._do_close()
  File "/home/aweshwep/virtualenv/astrology.jowibtechnologies.com/3.10/lib64/python3.10/site-packages/sqlalchemy/engine/base.py", line 2721, in _do_close
    self._close_impl()
  File "/home/aweshwep/virtualenv/astrology.jowibtechnologies.com/3.10/lib64/python3.10/site-packages/sqlalchemy/engine/base.py", line 2707, in _close_impl
    self._connection_rollback_impl()
  File "/home/aweshwep/virtualenv/astrology.jowibtechnologies.com/3.10/lib64/python3.10/site-packages/sqlalchemy/engine/base.py", line 2699, in _connection_rollback_impl
    self.connection._rollback_impl()
  File "/home/aweshwep/virtualenv/astrology.jowibtechnologies.com/3.10/lib64/python3.10/site-packages/sqlalchemy/engine/base.py", line 1124, in _rollback_impl
    self._handle_dbapi_exception(e, None, None, None, None)
  File "/home/aweshwep/virtualenv/astrology.jowibtechnologies.com/3.10/lib64/python3.10/site-packages/sqlalchemy/engine/base.py", line 2349, in _handle_dbapi_exception
    raise sqlalchemy_exception.with_traceback(exc_info[2]) from e
  File "/home/aweshwep/virtualenv/astrology.jowibtechnologies.com/3.10/lib64/python3.10/site-packages/sqlalchemy/engine/base.py", line 1122, in _rollback_impl
    self.engine.dialect.do_rollback(self.connection)
  File "/home/aweshwep/virtualenv/astrology.jowibtechnologies.com/3.10/lib64/python3.10/site-packages/sqlalchemy/engine/default.py", line 704, in do_rollback
    dbapi_connection.rollback()
  File "/home/aweshwep/virtualenv/astrology.jowibtechnologies.com/3.10/lib/python3.10/site-packages/pymysql/connections.py", line 493, in rollback
    self._read_ok_packet()
  File "/home/aweshwep/virtualenv/astrology.jowibtechnologies.com/3.10/lib/python3.10/site-packages/pymysql/connections.py", line 455, in _read_ok_packet
    raise err.OperationalError(
sqlalchemy.exc.OperationalError: (pymysql.err.OperationalError) (2014, 'Command Out of Sync')
(Background on this error at: https://sqlalche.me/e/20/e3q8)
[2025-08-14 02:17:53,772] ERROR in app: Exception on /api/services [GET]
Traceback (most recent call last):
  File "/home/aweshwep/virtualenv/astrology.jowibtechnologies.com/3.10/lib64/python3.10/site-packages/sqlalchemy/engine/base.py", line 1961, in _exec_single_context
    self.dialect.do_execute(
  File "/home/aweshwep/virtualenv/astrology.jowibtechnologies.com/3.10/lib64/python3.10/site-packages/sqlalchemy/engine/default.py", line 944, in do_execute
    cursor.execute(statement, parameters)
  File "/home/aweshwep/virtualenv/astrology.jowibtechnologies.com/3.10/lib/python3.10/site-packages/pymysql/cursors.py", line 153, in execute
    result = self._query(query)
  File "/home/aweshwep/virtualenv/astrology.jowibtechnologies.com/3.10/lib/python3.10/site-packages/pymysql/cursors.py", line 322, in _query
    conn.query(q)
  File "/home/aweshwep/virtualenv/astrology.jowibtechnologies.com/3.10/lib/python3.10/site-packages/pymysql/connections.py", line 563, in query
    self._affected_rows = self._read_query_result(unbuffered=unbuffered)
  File "/home/aweshwep/virtualenv/astrology.jowibtechnologies.com/3.10/lib/python3.10/site-packages/pymysql/connections.py", line 825, in _read_query_result
    result.read()
  File "/home/aweshwep/virtualenv/astrology.jowibtechnologies.com/3.10/lib/python3.10/site-packages/pymysql/connections.py", line 1199, in read
    first_packet = self.connection._read_packet()
  File "/home/aweshwep/virtualenv/astrology.jowibtechnologies.com/3.10/lib/python3.10/site-packages/pymysql/connections.py", line 744, in _read_packet
    packet_header = self._read_bytes(4)
  File "/home/aweshwep/virtualenv/astrology.jowibtechnologies.com/3.10/lib/python3.10/site-packages/pymysql/connections.py", line 798, in _read_bytes
    raise err.OperationalError(
pymysql.err.OperationalError: (2013, 'Lost connection to MySQL server during query')

The above exception was the direct cause of the following exception:

Traceback (most recent call last):
  File "/home/aweshwep/virtualenv/astrology.jowibtechnologies.com/3.10/lib/python3.10/site-packages/flask/app.py", line 1511, in wsgi_app
    response = self.full_dispatch_request()
  File "/home/aweshwep/virtualenv/astrology.jowibtechnologies.com/3.10/lib/python3.10/site-packages/flask/app.py", line 919, in full_dispatch_request
    rv = self.handle_user_exception(e)
  File "/home/aweshwep/virtualenv/astrology.jowibtechnologies.com/3.10/lib/python3.10/site-packages/flask_cors/extension.py", line 176, in wrapped_function
    return cors_after_request(app.make_response(f(*args, **kwargs)))
  File "/home/aweshwep/virtualenv/astrology.jowibtechnologies.com/3.10/lib/python3.10/site-packages/flask/app.py", line 917, in full_dispatch_request
    rv = self.dispatch_request()
  File "/home/aweshwep/virtualenv/astrology.jowibtechnologies.com/3.10/lib/python3.10/site-packages/flask/app.py", line 902, in dispatch_request
    return self.ensure_sync(self.view_functions[rule.endpoint])(**view_args)  # type: ignore[no-any-return]
  File "/home/aweshwep/astrology.jowibtechnologies.com/app/routes/services.py", line 8, in get_services
    services = Service.query.all()
  File "/home/aweshwep/virtualenv/astrology.jowibtechnologies.com/3.10/lib64/python3.10/site-packages/sqlalchemy/orm/query.py", line 2704, in all
    return self._iter().all()  # type: ignore
  File "/home/aweshwep/virtualenv/astrology.jowibtechnologies.com/3.10/lib64/python3.10/site-packages/sqlalchemy/orm/query.py", line 2857, in _iter
    result: Union[ScalarResult[_T], Result[_T]] = self.session.execute(
  File "/home/aweshwep/virtualenv/astrology.jowibtechnologies.com/3.10/lib64/python3.10/site-packages/sqlalchemy/orm/session.py", line 2365, in execute
    return self._execute_internal(
  File "/home/aweshwep/virtualenv/astrology.jowibtechnologies.com/3.10/lib64/python3.10/site-packages/sqlalchemy/orm/session.py", line 2251, in _execute_internal
    result: Result[Any] = compile_state_cls.orm_execute_statement(
  File "/home/aweshwep/virtualenv/astrology.jowibtechnologies.com/3.10/lib64/python3.10/site-packages/sqlalchemy/orm/context.py", line 306, in orm_execute_statement
    result = conn.execute(
  File "/home/aweshwep/virtualenv/astrology.jowibtechnologies.com/3.10/lib64/python3.10/site-packages/sqlalchemy/engine/base.py", line 1413, in execute
    return meth(
  File "/home/aweshwep/virtualenv/astrology.jowibtechnologies.com/3.10/lib64/python3.10/site-packages/sqlalchemy/sql/elements.py", line 526, in _execute_on_connection
    return connection._execute_clauseelement(
  File "/home/aweshwep/virtualenv/astrology.jowibtechnologies.com/3.10/lib64/python3.10/site-packages/sqlalchemy/engine/base.py", line 1635, in _execute_clauseelement
    ret = self._execute_context(
  File "/home/aweshwep/virtualenv/astrology.jowibtechnologies.com/3.10/lib64/python3.10/site-packages/sqlalchemy/engine/base.py", line 1840, in _execute_context
    return self._exec_single_context(
  File "/home/aweshwep/virtualenv/astrology.jowibtechnologies.com/3.10/lib64/python3.10/site-packages/sqlalchemy/engine/base.py", line 1980, in _exec_single_context
    self._handle_dbapi_exception(
  File "/home/aweshwep/virtualenv/astrology.jowibtechnologies.com/3.10/lib64/python3.10/site-packages/sqlalchemy/engine/base.py", line 2349, in _handle_dbapi_exception
    raise sqlalchemy_exception.with_traceback(exc_info[2]) from e
  File "/home/aweshwep/virtualenv/astrology.jowibtechnologies.com/3.10/lib64/python3.10/site-packages/sqlalchemy/engine/base.py", line 1961, in _exec_single_context
    self.dialect.do_execute(
  File "/home/aweshwep/virtualenv/astrology.jowibtechnologies.com/3.10/lib64/python3.10/site-packages/sqlalchemy/engine/default.py", line 944, in do_execute
    cursor.execute(statement, parameters)
  File "/home/aweshwep/virtualenv/astrology.jowibtechnologies.com/3.10/lib/python3.10/site-packages/pymysql/cursors.py", line 153, in execute
    result = self._query(query)
  File "/home/aweshwep/virtualenv/astrology.jowibtechnologies.com/3.10/lib/python3.10/site-packages/pymysql/cursors.py", line 322, in _query
    conn.query(q)
  File "/home/aweshwep/virtualenv/astrology.jowibtechnologies.com/3.10/lib/python3.10/site-packages/pymysql/connections.py", line 563, in query
    self._affected_rows = self._read_query_result(unbuffered=unbuffered)
  File "/home/aweshwep/virtualenv/astrology.jowibtechnologies.com/3.10/lib/python3.10/site-packages/pymysql/connections.py", line 825, in _read_query_result
    result.read()
  File "/home/aweshwep/virtualenv/astrology.jowibtechnologies.com/3.10/lib/python3.10/site-packages/pymysql/connections.py", line 1199, in read
    first_packet = self.connection._read_packet()
  File "/home/aweshwep/virtualenv/astrology.jowibtechnologies.com/3.10/lib/python3.10/site-packages/pymysql/connections.py", line 744, in _read_packet
    packet_header = self._read_bytes(4)
  File "/home/aweshwep/virtualenv/astrology.jowibtechnologies.com/3.10/lib/python3.10/site-packages/pymysql/connections.py", line 798, in _read_bytes
    raise err.OperationalError(
sqlalchemy.exc.OperationalError: (pymysql.err.OperationalError) (2013, 'Lost connection to MySQL server during query')
[SQL: SELECT services.id AS services_id, services.card_id AS services_card_id, services.title AS services_title, services.img AS services_img, services.description AS services_description, services.route AS services_route, services.link AS services_link, services.fields AS services_fields 
FROM services]
(Background on this error at: https://sqlalche.me/e/20/e3q8)
